Workbook

Sheet Commande Journaliere
A1: Les Essentiels
A2: Louis | C2: Pomona | E2: Transgourmet
A3: Beurre | C3: Parmesan rapé | E3: Canapin Blanc
A4: Lait | C4: Magret Fumé | E4: Canapin Couleur
A5: Creme UHT | C5: Saucisse Montbé | E5: Gros Sel
A6: Farine | C6: pavé Selle agneau | E6: Creme Isigny
A7: Sucre Semoule | C7: Fromage Blc | E7: Concentré Tomates
A8: Oeufs | C8: Mimo Boule | E8: Emmental Rapé
A9: Purée Fruit | C9: Chèvre Long | E9: Moutarde Dijon
A10: Gélatine | C10: Chair Crabe | E10: mini Fond rond
A11: Fromage Tranches | C11: Pains Suedois | E11: Pain nordique
A12: Sel Fin | C12: Blinis | E12: tomate confite
A13: Film Ali | E13: Abricot Sec
A14: Paille de Fer | C14: Episaveur | E14: Epinard
C15: Cornichon aigre doux | E15: Lardons
A16: Loste | C16: Sac sous vide 25.35 | E16: Ris Veau
A17: Jambon Blanc | C17: Sac sous vide 30.40 | E17: Foie Gras
A18: Jambon Cru | C18: Godet aluminium | E18: Huile Friture
A19: Rosette | C19: Pic Bambou | E19: Huile Tournesol
A20: Chorizo | C20: Mini Cuillere
A21: Gambas Mariné | C21: Gant Latex | E21: Goeland
A22: Boudin Blanc | C22: Riz Long Grain
C23: Riz Exquisiotto | E23: St Jacques
C24: Fleur de Sel | E24: Saumon Fumé
C25: Vinaigre Balsa Noir | E25: Filet Saumon
C26: Vinaigre Balsa blc | E26: Dos Cabillaud

Sheet INVENTAIRE
A1: STOCK CHATEAU MORBECQUE 2020
A3: FOURNISSEUR | B3: Nombre de Reference | C3: Total
A5: LOSTE | B5: 60 | C5: =Loste!G66 -> 207.19
A6: TRANSGOURMET | B6: 112 | C6: =Transgourmet!H145 -> 1287.058
A7: EPISAVEUR | B7: 75 | C7: =Episaveur!H86 -> 334.7386
A8: ECOLAB | B8: 9 | C8: =ECOLAB!G14 -> 17.9255
A9: PASSION FROID | B9: 25 | C9: ='Passion Froid'!H34 -> 36.508133
A10: FOURNISSEUR PATISSERIE | C10: ='Commande Via Patisserie'!G33 -> 0
A11: GOELAND | B11: 5 | C11: =Goeland!G12 -> 298
A12: POLLET | B12: 1 | C12: =Pollet!G9 -> 128.316
B14: TOTAL STOCK | C14: =SUM(C5:C11) -> 2181.4202

Sheet Loste
A2: Nom du Produit | B2: ref | C2: Unité | D2: Prix | E2: Date MAJ | F2: Stock | G2: Total
A3: 1/2 Bressaola 1k5 | B3: 43054 | C3: KG | D3: 25 | E3: 43891 | F3: 1.5 | G3: =D3*F3 -> 37.5
A4: Andouille Campagnarde | B4: 3350 | C4: KG | D4: 13.002 | E4: 43891 | G4: =D4*F4 -> 0
A5: Bacon Kassler 9.69 | B5: 9.69 | C5: KG | D5: 9.69 | E5: 43891 | G5: =D5*F5 -> 0
A6: Boudin Blanc aux Morilles 20Piece | B6: 3820 | C6: KG | D6: 8.871 | E6: 43891 | G6: =D6*F6 -> 0
A7: Boundin Blanc Fine Champagne | B7: 703 | C7: KG | D7: 7.57 | E7: 43891 | G7: =D7*F7 -> 0
A8: Chipolatas Chèvre Miel 3. Piece | B8: 43206 | C8: KG | D8: 9.89 | E8: 43891 | G8: =D8*F8 -> 0
A9: ChipolataS Herbes 20 pce | B9: 42012 | C9: KG | D9: 9.32 | E9: 43891 | G9: =D9*F9 -> 0
A10: Chipolatas par 40 | B10: 3611 | C10: KG | D10: 8.23 | E10: 43891 | G10: =D10*F10 -> 0
A11: Chipolatas Piment Esp 20Pièces | B11: 42030 | C11: KG | D11: 10.03 | E11: 43891 | G11: =D11*F11 -> 0
A12: Chorizo a Cuir 20 Pce | B12: 42013 | C12: KG | D12: 8.944 | E12: 43891 | G12: =D12*F12 -> 0
A13: Chorizo Ibérico | B13: 4112 | C13: KG | D13: 15.6 | E13: 43891 | G13: =D13*F13 -> 0
A14: Chorizo Regop 1k6 | B14: 3094 | C14: KG | D14: 11.72 | E14: 43891 | G14: =D14*F14 -> 0
A15: Coeur de Jambon Serrano | B15: 4419 | C15: KG | D15: 11.8 | E15: 43891 | G15: =D15*F15 -> 0
A16: Cofiolino 2k8 | B16: 2166 | C16: KG | D16: 19.4 | E16: 43891 | G16: =D16*F16 -> 0
A17: Coppa Corse 1k5 | B17: 5275 | C17: KG | D17: 17.91 | E17: 43891 | G17: =D17*F17 -> 0
... A20: Emincé de Pastramis 300g x 4 | B20: 4935 | C20: KG | D20: 19.499 | E20: 43891 | G20: =D20*F20 -> 0
A21: Gambas à L'ail 1kg7 | C21: KG | D21: 23.779 | E21: 43891 | G21: =D21*F21 -> 0
A22: Gambas Au Curry Doux 1k9 | C22: KG | D22: 20.981 | E22: 43891 | G22: =D22*F22 -> 0
A23: JAmbon Ficelle Fumé | B23: 4114 | C23: KG | D23: 7.7 | E23: 43891 | G23: =D23*F23 -> 0
A24: Jambon Fumé HdF | B24: 51206 | C24: KG | D24: 7.779 | E24: 43891 | G24: =D24*F24 -> 0
A25: Jambon Ibérique 12mois | B25: 4868 | C25: KG | D25: 41 | E25: 43891 | F25: 0.2 | G25: =D25*F25 -> 8.2
A26: Jambon LE Noir de Bigorre | B26: 4425 | C26: KG | D26: 45 | E26: 43891 | G26: =D26*F26 -> 0
A27: Jambon Parme 14Mois | B27: 5108 | C27: Kg | D27: 19.72 | E27: 43891 | G27: =D27*F27 -> 0
A28: Jambon San Daniele 22 24 Mois | B28: 43136 | C28: KG | D28: 23.45 | E28: 43891 | F28: 4.2 | G28: =D28*F28 -> 98.49
A29: Jesus 1k5 | B29: 43210 | C29: KG | D29: 14.491 | E29: 43891 | G29: =D29*F29 -> 0
A30: Lonzo Corse 1KG | B30: 5277 | C30: KG | D30: 20.306 | E30: 43891 | G30: =D30*F30 -> 0
A31: Magret de Canard 350g | B31: 43328 | C31: KG | D31: 11.9 | E31: 43891 | G31: =D31*F31 -> 0
A32: Merano Speck 2KG | B32: 3402 | C32: KG | D32: 14.215 | E32: 43891 | G32: =D32*F32 -> 0
A33: Merguez Forte 20 pièces | B33: 42024 | C33: KG | D33: 8.709 | E33: 43891 | G33: =D33*F33 -> 0
A34: Mini Artichaud 1KG | C34: KG | D34: 14.647 | E34: 43891 | G34: =D34*F34 -> 0
A35: Mini Chorizo | B35: 42014 | C35: KG | D35: 10.08 | E35: 43891 | G35: =D35*F35 -> 0
A36: Mini Saucisse a Grille | B36: 1074 | C36: KG | D36: 9.86 | E36: 43891 | G36: =D36*F36 -> 0
A37: Mousse de foie 2k2 | B37: 392 | C37: KG | D37: 11.901 | E37: 43891 | G37: =D37*F37 -> 0
A38: Mousse de foie Champi 2k45 | B38: 317 | C38: KG | D38: 9.924 | E38: 43891 | G38: =D38*F38 -> 0
A39: Mozzarella Di Buffala 250g | B39: 43215 | C39: Piece | D39: 3.949 | E39: 43891 | G39: =D39*F39 -> 0
A40: Mrtadelle Italienne 7KG | B40: 5113 | C40: KG | D40: 9.4 | E40: 43891 | G40: =D40*F40 -> 0
A41: Noix de Jambon Fumé | B41: 4857 | C41: KG | D41: 13.79 | E41: 43891 | G41: =D41*F41 -> 0
A42: Pancetta Salé | B42: 3074 | C42: KG | D42: 14.978 | E42: 43891 | G42: =D42*F42 -> 0
A43: Pate Campagne 3,8Kg | B43: 362 | C43: KG | D43: 8.91 | E43: 43891 | G43: =D43*F43 -> 0
...

Sheet ECOLAB
A1: Nom du Produit | B1: ref | C1: Unité | D1: Prix | E1: Date MAJ | F1: Stock | G1: Total
A3: KITCHEN PRO | B3: 209184 | C3: Bouteille | D3: 26.7 | E3: 43983 | G3: =F3*D3 -> 0
A4: MAGIC MAXX2 | B4: 253689 | C4: Bouteille | D4: 28.504 | E4: 43983 | G4: =F4*D4 -> 0
A5: GREASECUTTER | B5: 970672 | C5: Bouteille | D5: 35.851 | E5: 43983 | F5: 0.5 | G5: =F5*D5 -> 17.9255
A6: MAXX INTO C2 | B6: 202203 | C6: Bouteille | D6: 4.721 | E6: 43983 | G6: =F6*D6 -> 0
A7: OASIS PRO TOILET | B7: 240080 | C7: Bouteille | D7: 68.122 | E7: 43983 | G7: =F7*D7 -> 0
A8: MAGIC MAXX2 | B8: 253689 | C8: Bouteille | D8: 28.504 | E8: 43983 | G8: =F8*D8 -> 0
A9: OASIS CLEAN 40 | B9: 209199 | C9: Bouteille | D9: 76.803 | E9: 43983 | G9: =F9*D9 -> 0
A10: OASIS PRO GLASS | B10: 240083 | C10: Bouteille | D10: 89.847 | E10: 43983 | G10: =F10*D10 -> 0
A11: Polish Cleaner | B11: 778062 | C11: Bouteille | D11: 9.964 | E11: 43983 | G11: =F11*D11 -> 0
A12: Solid Multi Lave Vaiselle | B12: 778213 | C12: Colis 4 | D12: 273.06
A13: TopRinse | B13: 200750 | C13: Bidon | D13: 112.62
B14: STOCK TOTAL ECOLAB | G14: =SUM(G3:G11) -> 17.9255

Sheet Transgourmet
A1: Nom du Produit | B1: ref | C1: Conditionement | D1: Unité | E1: Prix | F1: Date MAJ | G1: Stock | H1: Total
A2: L'EPICERIE
A3: Abricot Moelleux | B3: 676965 | C3: 1 | D3: KG | E3: 9.3 | F3: 43862 | G3: 2 | H3: =E3*G3 -> 18.6
A4: Abricot Oreillon Sirop | B4: 250320 | C4: 820g | D4: KG | E4: 2.34 | F4: 43862 | H4: =E4*G4 -> 0
A5: Ail Semoule | B5: 300524 | C5: 500g | D5: Pot | E5: 8.9 | F5: 44013 | G5: 0.5 | H5: =E5*G5 -> 4.45
A6: Arome Patrelle | B6: 21550 | C6: 1L | D6: Bouteille | E6: 10.45 | F6: 43983 | G6: 1 | H6: =E6*G6 -> 10.45
A7: Badiane Entiere | B7: 206919 | C7: 1Kg | D7: Kg | E7: 45 | F7: 44013 | G7: 0.22 | H7: =E7*G7 -> 9.9
A8: Bouillon volaille | B8: 23442 | C8: 750g | D8: Boite | E8: 7.97 | F8: 43862 | H8: =E8*G8 -> 0
A9: Canelle Moulue | B9: 252122 | C9: 390g | D9: Boite | E9: 16.52 | F9: 44013 | G9: 0.25 | H9: =E9*G9 -> 4.13
A10: Capre | B10: 300153 | C10: 800g | D10: Boite | E10: 2.88 | F10: 43862 | H10: =E10*G10 -> 0
A11: cepes secher | B11: 300235 | C11: 500g | D11: Boite | E11: 13.44 | F11: 43862 | H11: =E11*G11 -> 0
A12: Cereales Gourmande Tipiak | B12: 800632 | C12: 4,5Kg | D12: Sachet | E12: 10.67 | F12: 44013 | G12: 2 | H12: =E12*G12 -> 21.34
A13: Cernaux noix | B13: 300971 | C13: 1Kg | D13: Sachet | E13: 9.39 | F13: 43862 | H13: =E13*G13 -> 0
A14: Clous de Girofles | B14: 412643 | C14: 165g | D14: Boite | E14: 10.25 | F14: 44013 | G14: 0.6 | H14: =E14*G14 -> 6.15
A15: Concentré Tomates 4/4 | B15: 300172 | C15: Boite4/4 | D15: Boite | E15: 1.52 | F15: 43862 | G15: 1 | H15: =E15*G15 -> 1.52
A16: Coriandre Graine | B16: 252221 | C16: 230g | D16: Boite | E16: 4.66 | F16: 44013 | G16: 0.5 | H16: =E16*G16 -> 2.33
A17: Cumin Moulu | B17: 252163 | C17: 400g | D17: Boite | E17: 14.67 | F17: 44013 | G17: 0.9 | H17: =E17*G17 -> 13.203
A18: Curry Kg Sachet | B18: 300504 | C18: 1kg | D18: sachet | E18: 5.24 | F18: 43862 | H18: =E18*G18 -> 0
A19: Epice Cajun | B19: 195612 | C19: 220g | D19: Boite | E19: 7.04 | F19: 44013 | G19: 0.5 | H19: =E19*G19 -> 3.52
A20: Escargot | B20: 213077 | C20: 800g | D20: boite | E20: 8.61 | F20: 43862 | H20: =E20*G20 -> 0
A21: Fond Volaille Knor | B21: 874635 | C21: 750g | D21: boite | E21: 8.19 | F21: 43862 | G21: 0.8 | H21: =E21*G21 -> 6.552
A22: Graine Pavot | B22: 805374 | C22: 1Kg | D22: Sachet | E22: 13.94 | F22: 44013 | G22: 1 | H22: =E22*G22 -> 13.94
A23: Graine Chia | B23: 216612 | C23: 500g | D23: sachet | E23: 4.45 | F23: 43862 | G23: 1 | H23: =E23*G23 -> 4.45
A24: Graine courge | B24: 248622 | C24: 1Kg | D24: sachet | E24: 8.55 | F24: 43862 | G24: 0.72 | H24: =E24*G24 -> 6.156
A25: Graisse Canard | B25: 806612 | C25: 3.5kg | D25: boite | E25: 15.49 | F25: 43862 | H25: =E25*G25 -> 0
A26: Herbes de Provence | B26: 300508 | C26: 1Kg | D26: KG | E26: 9.15 | F26: 44013 | G26: 0.4 | H26: =E26*G26 -> 3.66
A27: Huile Noisette | B27: 192040 | C27: 500ml | D27: bouteille | E27: 5.93 | F27: 43862 | G27: 0.2 | H27: =E27*G27 -> 1.186
A28: Huile Tournesol 1L | B28: 300004 | C28: 1L | D28: bouteille | E28: 1.41 | F28: 43862 | G28: 3 | H28: =E28*G28 -> 4.23
A29: Huile Tournesol 5L | B29: 300862 | C29: 5L | D29: bidon | E29: 6.67 | F29: 43862 | G29: 1.2 | H29: =E29*G29 -> 8.004
A30: Huiles Olives Extra | B30: 300863 | C30: 5L | D30: bidon | E30: 25.7 | F30: 43862 | H30: =E30*G30 -> 0
A31: Lait Amande | B31: 207098 | C31: 1L | D31: bouteille | E31: 6.18 | F31: 43862 | H31: =E31*G31 -> 0
A32: Lentille Corail | B32: 207095 | C32: 2,5Kg | D32: sachet | E32: 5.93 | F32: 43862 | H32: =E32*G32 -> 0
A33: Miel | B33: 473868 | C33: 1Kg | D33: Pot | E33: 4.76 | F33: 43862 | G33: 1 | H33: =E33*G33 -> 4.76
A34: mini fond carré | B34: 209563 | C34: 225Portion | D34: Carton | E34: 50.778 | F34: 43862 | H34: =E34*G34 -> 0
A35: MiniFond Rond | B35: 20964 | C35: 200Portion | D35: Carton | E35: 38.493 | F35: 43862 | G35: 2 | H35: =E35*G35 -> 76.986
A36: Mise en place Pesto Rouge | B36: 474437 | C36: 340g | D36: Pot | E36: 11.48 | F36: 43983 | G36: 1 | H36: =E36*G36 -> 11.48
A37: Mix Oriental Kebab | B37: 424879 | C37: 240g | D37: Boite | E37: 14.08 | F37: 44013 | G37: 0.5 | H37: =E37*G37 -> 7.04
A38: Muscade Pourdre | B38: 300509 | C38: 1kg | D38: Kg | E38: 33.37 | F38: 44013 | G38: 0.8 | H38: =E38*G38 -> 26.696
A39: Olives Kalmata | B39: 250598 | C39: 1Kg | D39: Bocal | E39: 9.621 | F39: 43862 | G39: 0.5 | H39: =E39*G39 -> 4.8105
A40: panko | B40: 203623 | C40: 1Kg | D40: Sachet | E40: 5.58 | F40: 43862 | G40: 2 | H40: =E40*G40 -> 11.16
...

Sheet Passion Froid
A1: Nom du Produit | B1: ref | C1: Conditionement | D1: Unité | E1: Prix | F1: Date MAJ | G1: Stock | H1: Total
A2: B.O.F
A3: Fromage Blanc isigny | B3: 49823 | C3: 5K | D3: Seau | E3: 4.006 | F3: 43983 | H3: =E3*G3 -> 0
A4: Parmesan Rapé | B4: 171705 | C4: 1Kg | D4: KG | E4: 17.99 | F4: 43983 | G4: 0.8 | H4: =E4*G4 -> 14.392
A5: Brie Meaux Aop | B5: 58532 | C5: 750g | D5: Roue | E5: 15.95 | F5: 43983 | H5: =E5*G5 -> 0
A6: Ecume wirmereux 200g | B6: 194260 | C6: 200g | D6: Piece | E6: 3.55 | F6: 43983 | H6: =E6*G6 -> 0
A7: chevre long 180g | B7: 170229 | C7: 180g | D7: Piece | E7: 1.614 | F7: 43983 | H7: =E7*G7 -> 0
A8: Fort d'ambleuteuse | B8: 57903 | C8: 400g | D8: Pièce | E8: 7.93 | F8: 43983 | H8: =E8*G8 -> 0
A9: Gouda | B9: 137716 | C9: 300g | D9: Pièce | E9: 19.681 | F9: 43983 | H9: =E9*G9 -> 0
A10: Mimolette boule | B10: 99568 | C10: 1,9Kg | D10: Kg | E10: 7.27 | F10: 43983 | H10: =E10*G10 -> 0
A11: Mimolette Extra veille | B11: 11940 | C11: 3kg | D11: Kg | E11: 21.709 | F11: 43983 | H11: =E11*G11 -> 0
A12: Ossau iraty | B12: 58585 | C12: 400g | D12: Kg | E12: 17.26 | F12: 43983 | H12: =E12*G12 -> 0
A13: Pavé Leffe | B13: 183788 | C13: 3,23Kg | D13: KG | E13: 20.837 | F13: 43983 | H13: =E13*G13 -> 0
A14: Reblochon | B14: 44364 | C14: 500g | D14: kg | E14: 10.871 | F14: 43983 | H14: =E14*G14 -> 0
A16: Viandes & Charcuteries
A17: Mortadelle | B17: 155637 | C17: 5,9Kg | D17: KG | E17: 7.34 | F17: 43983 | H17: =E17*G17 -> 0
A18: Saucisse Fumé | B18: 6472 | C18: 125g | D18: KG | E18: 8.22 | F18: 43983 | H18: =E18*G18 -> 0
A19: Saucisse Montbéliard | B19: 37499 | C19: 120g | D19: KG | E19: 11.907 | F19: 43983 | G19: 1 | H19: =E19*G19 -> 11.907
A20: Saucisson du marin | B20: 185057 | C20: 700g/1.5kg | D20: KG | E20: 19.163 | F20: 43983 | H20: =E20*G20 -> 0
A21: pavé Selle agneau | B21: 196271 | C21: 6 pièces | D21: KG | E21: 19.3 | F21: 43983 | H21: =E21*G21 -> 0
A22: Carré de Porc | B22: 98721 | C22: 3Kg | D22: KG | E22: 6.55 | F22: 43983 | H22: =E22*G22 -> 0
A23: Entrecote de veau | B23: 192139 | C23: 1,2 1,6Kg | D23: KG | E23: 16.95 | F23: 43983 | H23: =E23*G23 -> 0
A24: saucisson ail Fumé | B24: 2210 | C24: 1Kg | D24: KG | E24: 5.072 | F24: 43983 | H24: =E24*G24 -> 0
A25: Magret de Canard Fumé | B25: 36647 | C25: 280g | D25: KG | E25: 30.58 | F25: 43983 | G25: 0.26 | H25: =E25*G25 -> 7.9508
A26: Poissons
A27: Chair Crabe | B27: 7235 | C27: Boite 450g | D27: KG | E27: =(17/450)*1000 -> 37.777778 | F27: 43983 | H27: =E27*G27 -> 0
A29: Surgelé
A30: Blinis | B30: 98484 | C30: Carton 180 | D30: Carton | E30: 13.55 | F30: 43983 | G30: =1/6 -> 0.16666667 | H30: =E30*G30 -> 2.2583333
A31: Pain Suédois | B31: 24728 | C31: Carton 84Piece | D31: Piece | E31: 0.25 | F31: 43983 | H31: =E31*G31 -> 0
C34: STOCK POMONA | H34: =SUM(H3:H31) -> 36.508133

Sheet Episaveur
A1: Nom du Produit | B1: ref | C1: Conditionement | D1: Unité | E1: Prix | F1: Date MAJ | G1: Stock | H1: Total
A2: Abricot sec | B2: 5057 | C2: 1 | D2: KG | E2: 4.25 | F2: 43983 | H2: =E2*G2 -> 0
A3: Abricot Sirop 4/4 | B3: 40838 | C3: 4 4 | D3: Boite | E3: 1.59 | F3: 43983 | H3: =E3*G3 -> 0
A4: Ail Noir | B4: 203522 | C4: 140g | D4: g | E4: 17.619 | F4: 43983 | H4: =E4*G4 -> 0
A5: Baie goji EDC sac 200G | B5: 203486 | C5: 200g | D5: KG | E5: 7.7 | F5: 43983 | H5: =E5*G5 -> 0
A6: Beurre Cacahuète | B6: 67839 | C6: 500g | D6: KG | E6: 6.82 | F6: 43983 | G6: 1 | H6: =E6*G6 -> 6.82
A7: Bouillon dashi | B7: 180932 | C7: 60g | D7: 60G | E7: 22.4 | F7: 43983 | H7: =E7*G7 -> 0
A8: Cacahuete Grillé | B8: 62423 | C8: 1kg | D8: KG | E8: 5.34 | F8: 43983 | G8: 0.2 | H8: =E8*G8 -> 1.068
A9: Capron | B9: 98768 | C9: 44 | D9: Boite | E9: 3.2 | F9: 43983 | H9: =E9*G9 -> 0
A10: Cardamome | B10: 203473 | C10: 100g | D10: Sachet | E10: 11.631 | F10: 44013 | G10: 1 | H10: =E10*G10 -> 11.631
A11: chapelure blanche | B11: 43484 | C11: 1KG | D11: KG | E11: 2.12 | F11: 43983 | H11: =E11*G11 -> 0
A12: Coriandre entiere | B12: 44118 | C12: 280g | D12: POT | E12: 3.56 | F12: 43983 | H12: =E12*G12 -> 0
A13: Cornichon aigre doux | B13: 52987 | C13: 2.45KG | D13: BOCAL | E13: 5.041 | F13: 43983 | G13: 1 | H13: =E13*G13 -> 5.041
A14: Cornichon Bfroid | B14: 1878 | C14: 5 1 | D14: Boite | E14: 5.99 | F14: 43983 | H14: =E14*G14 -> 0
A15: Creme Balsamique | B15: 8346 | C15: 40cl | D15: Pipette | E15: 5.93 | F15: 43983 | G15: 2 | H15: =E15*G15 -> 11.86
A16: crozet | B16: 51337 | C16: 5KG | D16: KG | E16: =27.66/5 -> 5.532 | F16: 43983 | G16: 5 | H16: =E16*G16 -> 27.66
A17: Curry boite | B17: 10310 | C17: 440g | D17: Boite | E17: 6.64 | F17: 43983 | G17: 0.2 | H17: =E17*G17 -> 1.328
A18: Curry celtique EDC | B18: 203541 | C18: 200g | D18: Sachet | E18: 3.3 | F18: 43983 | H18: =E18*G18 -> 0
A19: Curry Madras EDC | B19: 203542 | C19: 200g | D19: Sachet | E19: 2.96 | F19: 43983 | H19: =E19*G19 -> 0
A20: Curry vert EDC | B20: 203543 | C20: 200g | D20: Sachet | E20: 6.6 | F20: 43983 | H20: =E20*G20 -> 0
A21: Ebly | B21: 43480 | C21: 5Kg | D21: KG | E21: =20.481/5 -> 4.0962 | F21: 43983 | G21: 2 | H21: =E21*G21 -> 8.1924
A22: Fenouil Entier | B22: 44165 | C22: 260g | D22: Boite | E22: 3.603 | F22: 43983 | G22: 0.1 | H22: =E22*G22 -> 0.3603
A23: Feve Tonka EDC | B23: 203526 | C23: 100g | D23: Sachet | E23: 6.48 | F23: 43983 | H23: =E23*G23 -> 0
A24: Figues | B24: 46920 | C24: 500g | D24: Sachet | E24: 4.257 | F24: 43983 | H24: =E24*G24 -> 0
A25: Fleur de Sel | B25: 94131 | C25: 500g | D25: Sachet | E25: 5.985 | F25: 43983 | G25: 2 | H25: =E25*G25 -> 11.97
A26: Graine Tournesol | B26: 205146 | C26: 500g | D26: Sachet | E26: 5.7 | F26: 44013 | G26: 0.1 | H26: =E26*G26 -> 0.57
A27: Gras de Boeuf | B27: 186551 | C27: 10kg | D27: KG | E27: 14.9 | F27: 43983 | H27: =E27*G27 -> 0
A28: Gros Sel | B28: 25150 | C28: 1KG | D28: KG | E28: 0.279 | F28: 43983 | G28: 8 | H28: =E28*G28 -> 2.232
A29: Huile Friture 7L | B29: 173471 | C29: 7L5 | D29: BIDON | E29: 14.9 | F29: 43983 | H29: =E29*G29 -> 0
A30: Jus citr yuzu | B30: 156887 | C30: 360ml | D30: ML | E30: 27.6 | F30: 43983 | H30: =E30*G30 -> 0
A31: Jus veau 40L | E31: 17.8 | F31: 43983 | G31: 1 | H31: =E31*G31 -> 17.8
A32: Kecthup Colona | B32: 26618 | C32: 3L | D32: Pot | E32: 9.073 | F32: 43983 | G32: 0.5 | H32: =E32*G32 -> 4.5365
A33: Lait coco 500ml | B33: 89825 | C33: 1L | D33: L | E33: 4.65 | F33: 43983 | H33: =E33*G33 -> 0
A34: Lasagne | B34: 25653 | C34: 3KG | D34: Boite | E34: 14.51 | F34: 43983 | H34: =E34*G34 -> 0
A35: Lingot du nord | B35: 169053 | C35: 2,5kg | D35: Sachet | E35: 2.2104 | F35: 43983 | G35: 4.5 | H35: =E35*G35 -> 9.9468
A36: Linguine Maestro | B36: 49610 | C36: 3Kg | D36: Sachet | E36: 7.3 | F36: 43983 | H36: =E36*G36 -> 0
A37: Macaroni | B37: 43359 | C37: 5KG | D37: KG | E37: 9.8 | F37: 43983 | G37: 5 | H37: =E37*G37 -> 49
A38: Mel 5 baie ent | B38: 203524 | C38: 130g | D38: KG | E38: 7.8 | F38: 43983 | H38: =E38*G38 -> 0
A39: Melange Thai | B39: 22251 | C39: 240g | D39: pot | E39: 7.15 | F39: 43983 | G39: 0.5 | H39: =E39*G39 -> 3.575
A40: Mini Fond Rect Filigrano | B40: 178600 | C40: 150pièce | D40: Carton | E40: 39.9 | F40: 43983 | H40: =E40*G40 -> 0
...

Sheet Commande Via Patisserie
A1: Nom du Produit | B1: Conditionement | C1: Unité | D1: Prix | E1: Date MAJ | F1: Stock | G1: Total
A3: Beurre | B3: 25Kg | C3: Motte | F3: 4.3 | G3: =D3*F3 -> 0
A4: Lait | F4: 2 | G4: =D4*F4 -> 0
A5: Creme UHT | G5: =D5*F5 -> 0
A6: Farine | F6: 3 | G6: =D6*F6 -> 0
A7: Sucre Semoule | F7: 6 | G7: =D7*F7 -> 0
A8: Oeufs | G8: =D8*F8 -> 0
A9: Purée Mangue | F9: 1
A10: Purée Mandarine | F10: 3 | G10: =D10*F10 -> 0
A11: Gélatine | G11: =D11*F11 -> 0
A12: Fromage Tranche | G12: =D12*F12 -> 0
A13: Canapin Blanc | G13: =D13*F13 -> 0
A14: Canapin Couleur | G14: =D14*F14 -> 0
A15: Poudre Amandes | F15: 5 | G15: =D15*F15 -> 0
A16: Poudre Noisettes | G16: =D16*F16 -> 0
A17: Graine | F17: 2 | G17: =D17*F17 -> 0
A18: Sucre Glace | F18: 1.6 | G18: =D18*F18 -> 0
A19: Pavot Bleue | G19: =D19*F19 -> 0
A20: Sésame | G20: =D20*F20 -> 0
A21: Noisette entiere | F21: 1 | G21: =D21*F21 -> 0
A22: Fleur de Carthame | F22: 1 | G22: =D22*F22 -> 0
A23: Huilé Basilic | F23: 1.25 | G23: =D23*F23 -> 0
A24: Savo Orange Sanguine | F24: 1.5 | G24: =D24*F24 -> 0
A25: Vin Jaune | F25: 0.5 | G25: =D25*F25 -> 0
A26: Mix Guacamole | F26: 0.15 | G26: =D26*F26 -> 0
A27: Arome Café | F27: 1 | G27: =D27*F27 -> 0
A28: Mini Poire | F28: 2 | G28: =D28*F28 -> 0
A29: Tapenade | F29: 6 | G29: =D29*F29 -> 0
A30: Porto | F30: 1 | G30: =D30*F30 -> 0
A31: Armagnac | F31: 1 | G31: =D31*F31 -> 0
A32: Huile Fumé | F32: 6 | G32: =D32*F32 -> 0
B33: STOCK PRODUITS PATISSERIE | G33: =SUM(G3:G29) -> 0

Sheet Pollet
A1: Nom du Produit | B1: Conditionement | C1: Unité | D1: Prix | E1: Date MAJ | F1: Stock | G1: Total
A3: Suprême de Poulet | B3: KG | C3: KG | D3: 5.55 | E3: 44013 | F3: 23.12 | G3: =D3*F3 -> 128.316
A4: Poulet Standard | B4: Piece | C4: KG | D4: 2.42
B9: TOTAL STOCK Pollet | G9: =SUM(G3:G7) -> 128.316

Sheet Goeland
A1: Nom du Produit | B1: Conditionement | C1: Unité | D1: Prix | E1: Date MAJ | F1: Stock | G1: Total
A3: DOS CABILLAUD | B3: Colis 3KG | C3: KG | D3: 16.9 | E3: 43983 | F3: 2.1 | G3: =D3*F3 -> 35.49
A4: FILET SAUMON ECOSSE LABEL R | B4: Colis 15Kg | C4: KG | D4: 15.9 | E4: 44044 | F4: =7.4+2.6+3.6+0.6 -> 14.2 | G4: =D4*F4 -> 225.78
A5: DOS LIEU NOIR | B5: Colis 3KG | C5: KG | D5: 9.9 | E5: 43983 | F5: 2.2 | G5: =D5*F5 -> 21.78
A6: CHAIR CRABE | B6: 454g | C6: Boite | D6: 14.95 | E6: 43983 | F6: 1 | G6: =D6*F6 -> 14.95
A7: SAUMON FUME ECOSSE TRANC | B7: Filet | C7: KG | D7: 24.9 | E7: 44044 | G7: =D7*F7 -> 0
A8: NOIX ST JACQUES NON FR | B8: 2KG | C8: KG | D8: 23.9 | E8: 43983 | G8: =D8*F8 -> 0
A9: noix de dt jack ecosse | B9: 2kg | C9: kg | D9: 26.9 | E9: 44044 | G9: =D9*F9 -> 0
A10: filet eiglefin | B10: 3kg | C10: kg | D10: 9.9 | E10: 44044
C12: TOTAL STOCK GOELAND | G12: =SUM(G3:G9) -> 298
